Workbook

Sheet ToPowerBI
A1: Query | B1: ReportingStartDate | C1: ReportingEndDate | D1: Reporter | E1: UCITS_special mutual fund type | F1: Capital variability | G1: Fund category | H1: Fund Management Company | I1: AIF | J1: Status | K1: Lifetime (whole years) | L1: Row number
A2: PEF | B2: 39783 | C2: 43496 | D2: Placeringsfond SEB Money Manager | E2: UCITS | F2: Open-end | G2: Money market fund | H2: SEB | I2: Not found | J2: =IF(ISNUMBER(MATCH($D2,'Lopettaneet 2013->'!$D:$D,0)),INDEX('Lopettaneet 2013->'!$K:$K,MATCH($D2,'Lopettaneet 2013->'!$D:$D,0)),"Continues") -> Merged | K2: =IF($J2="Continues",DATEDIF($B2,TODAY(),"Y"),INDEX('Lopettaneet 2013->'!$L:$L,MATCH($D2,'Lopettaneet 2013->'!$D:$D,0))) -> 10 | L2: 1
A3: PEF | B3: 41974 | C3: 43100 | D3: Oy Wedeco Ab | E3: Non-UCITS | F3: Closed-end | G3: Buy-out fund | H3: Wedeco | I3: Not found | J3: =IF(ISNUMBER(MATCH($D3,'Lopettaneet 2013->'!$D:$D,0)),INDEX('Lopettaneet 2013->'!$K:$K,MATCH($D3,'Lopettaneet 2013->'!$D:$D,0)),"Continues") -> Closed | K3: =IF($J3="Continues",DATEDIF($B3,TODAY(),"Y"),INDEX('Lopettaneet 2013->'!$L:$L,MATCH($D3,'Lopettaneet 2013->'!$D:$D,0))) -> 3 | L3: 1
A4: MMF | B4: 39783 | C4: 43465 | D4: OP-Euro -sijoitusrahasto | E4: UCITS | F4: Open-end | G4: Bond fund | H4: Osuuspankki | I4: Retail | J4: =IF(ISNUMBER(MATCH($D4,'Lopettaneet 2013->'!$D:$D,0)),INDEX('Lopettaneet 2013->'!$K:$K,MATCH($D4,'Lopettaneet 2013->'!$D:$D,0)),"Continues") -> Closed | K4: =IF($J4="Continues",DATEDIF($B4,TODAY(),"Y"),INDEX('Lopettaneet 2013->'!$L:$L,MATCH($D4,'Lopettaneet 2013->'!$D:$D,0))) -> 10 | L4: 2
A5: PEF | B5: 41974 | C5: 42735 | D5: Finnventure Rahasto V Ky | E5: Non-UCITS | F5: Closed-end | G5: Buy-out fund | H5: Not found | I5: Not found | J5: =IF(ISNUMBER(MATCH($D5,'Lopettaneet 2013->'!$D:$D,0)),INDEX('Lopettaneet 2013->'!$K:$K,MATCH($D5,'Lopettaneet 2013->'!$D:$D,0)),"Continues") -> Closed | K5: =IF($J5="Continues",DATEDIF($B5,TODAY(),"Y"),INDEX('Lopettaneet 2013->'!$L:$L,MATCH($D5,'Lopettaneet 2013->'!$D:$D,0))) -> 2 | L5: 2
A6: MMF | B6: 41122 | C6: 43465 | D6: S-Pankki Lyhyt Korko Sijoitusrahasto | E6: UCITS | F6: Open-end | G6: Bond fund | H6: S-Pankki | I6: Retail | J6: =IF(ISNUMBER(MATCH($D6,'Lopettaneet 2013->'!$D:$D,0)),INDEX('Lopettaneet 2013->'!$K:$K,MATCH($D6,'Lopettaneet 2013->'!$D:$D,0)),"Continues") -> Closed | K6: =IF($J6="Continues",DATEDIF($B6,TODAY(),"Y"),INDEX('Lopettaneet 2013->'!$L:$L,MATCH($D6,'Lopettaneet 2013->'!$D:$D,0))) -> 6 | L6: 3
A7: PEF | B7: 41974 | C7: 42369 | D7: Maneq Fund 2002 Ky | E7: Non-UCITS | F7: Closed-end | G7: Buy-out fund | H7: Maneq | I7: Not found | J7: =IF(ISNUMBER(MATCH($D7,'Lopettaneet 2013->'!$D:$D,0)),INDEX('Lopettaneet 2013->'!$K:$K,MATCH($D7,'Lopettaneet 2013->'!$D:$D,0)),"Continues") -> Closed | K7: =IF($J7="Continues",DATEDIF($B7,TODAY(),"Y"),INDEX('Lopettaneet 2013->'!$L:$L,MATCH($D7,'Lopettaneet 2013->'!$D:$D,0))) -> 1 | L7: 3
A8: MMF | B8: 39783 | C8: 40908 | D8: Placeringsfonden Handelsbanken Euroränta | E8: UCITS | F8: Open-end | G8: Bond fund | H8: Handelsbanken | I8: Not found | J8: =IF(ISNUMBER(MATCH($D8,'Lopettaneet 2013->'!$D:$D,0)),INDEX('Lopettaneet 2013->'!$K:$K,MATCH($D8,'Lopettaneet 2013->'!$D:$D,0)),"Continues") -> Closed | K8: =IF($J8="Continues",DATEDIF($B8,TODAY(),"Y"),INDEX('Lopettaneet 2013->'!$L:$L,MATCH($D8,'Lopettaneet 2013->'!$D:$D,0))) -> 3 | L8: 4
A9: PEF | B9: 41974 | C9: 43738 | D9: Finnmezzanine Rahasto III A Ky | E9: Non-UCITS | F9: Closed-end | G9: Buy-out fund | H9: Finnmezzanine | I9: Not found | J9: =IF(ISNUMBER(MATCH($D9,'Lopettaneet 2013->'!$D:$D,0)),INDEX('Lopettaneet 2013->'!$K:$K,MATCH($D9,'Lopettaneet 2013->'!$D:$D,0)),"Continues") -> Closed | K9: =IF($J9="Continues",DATEDIF($B9,TODAY(),"Y"),INDEX('Lopettaneet 2013->'!$L:$L,MATCH($D9,'Lopettaneet 2013->'!$D:$D,0))) -> 4 | L9: 4
A10: MMF | B10: 40909 | C10: 41912 | D10: Placeringsfonden Handelsbanken Euroränta | E10: UCITS | F10: Open-end | G10: Bond fund | H10: Handelsbanken | I10: Not found | J10: =IF(ISNUMBER(MATCH($D10,'Lopettaneet 2013->'!$D:$D,0)),INDEX('Lopettaneet 2013->'!$K:$K,MATCH($D10,'Lopettaneet 2013->'!$D:$D,0)),"Continues") -> Closed | K10: =IF($J10="Continues",DATEDIF($B10,TODAY(),"Y"),INDEX('Lopettaneet 2013->'!$L:$L,MATCH($D10,'Lopettaneet 2013->'!$D:$D,0))) -> 3 | L10: 5
A11: PEF | B11: 41974 | C11: 42369 | D11: Finnmezzanine Rahasto III C Ky | E11: Non-UCITS | F11: Closed-end | G11: Buy-out fund | H11: Finnmezzanine | I11: Not found | J11: =IF(ISNUMBER(MATCH($D11,'Lopettaneet 2013->'!$D:$D,0)),INDEX('Lopettaneet 2013->'!$K:$K,MATCH($D11,'Lopettaneet 2013->'!$D:$D,0)),"Continues") -> Closed | K11: =IF($J11="Continues",DATEDIF($B11,TODAY(),"Y"),INDEX('Lopettaneet 2013->'!$L:$L,MATCH($D11,'Lopettaneet 2013->'!$D:$D,0))) -> 1 | L11: 5
A12: MMF | B12: 39783 | C12: 42277 | D12: Sijoitusrahasto Alfred Berg Korko | E12: UCITS | F12: Open-end | G12: Money market fund | H12: Evli | I12: Not found | J12: =IF(ISNUMBER(MATCH($D12,'Lopettaneet 2013->'!$D:$D,0)),INDEX('Lopettaneet 2013->'!$K:$K,MATCH($D12,'Lopettaneet 2013->'!$D:$D,0)),"Continues") -> Merged | K12: =IF($J12="Continues",DATEDIF($B12,TODAY(),"Y"),INDEX('Lopettaneet 2013->'!$L:$L,MATCH($D12,'Lopettaneet 2013->'!$D:$D,0))) -> 6 | L12: 6
A13: PEF | B13: 41974 | C13: 43738 | D13: Finnmezzanine Rahasto III B Ky | E13: Non-UCITS | F13: Closed-end | G13: Buy-out fund | H13: Finnmezzanine | I13: Not found | J13: =IF(ISNUMBER(MATCH($D13,'Lopettaneet 2013->'!$D:$D,0)),INDEX('Lopettaneet 2013->'!$K:$K,MATCH($D13,'Lopettaneet 2013->'!$D:$D,0)),"Continues") -> Closed | K13: =IF($J13="Continues",DATEDIF($B13,TODAY(),"Y"),INDEX('Lopettaneet 2013->'!$L:$L,MATCH($D13,'Lopettaneet 2013->'!$D:$D,0))) -> 4 | L13: 6
... A1356: PEF | B1356: 45352 | C1356: 55153 | D1356: NSI Feeder I Ky | E1356: Non-UCITS | F1356: Closed-end | G1356: Venture Capital fund | H1356: Nordic Science Investments Oy | I1356: Non-Retail | J1356: =IF(ISNUMBER(MATCH($D1356,'Lopettaneet 2013->'!$D:$D,0)),INDEX('Lopettaneet 2013->'!$K:$K,MATCH($D1356,'Lopettaneet 2013->'!$D:$D,0)),"Continues") -> Continues | K1356: =IF($J1356="Continues",DATEDIF($B1356,TODAY(),"Y"),INDEX('Lopettaneet 2013->'!$L:$L,MATCH($D1356,'Lopettaneet 2013->'!$D:$D,0))) -> 1 | L1356: 1091
A1357: PEF | B1357: 45444 | C1357: 55153 | D1357: OpenOcean Fund 2024 Ky | E1357: Non-UCITS | F1357: Closed-end | G1357: Venture Capital fund | H1357: OpenOcean Oy | I1357: Not found | J1357: Continues | K1357: =IF($J1357="Continues",DATEDIF($B1357,TODAY(),"Y"),INDEX('Lopettaneet 2013->'!$L:$L,MATCH($D1357,'Lopettaneet 2013->'!$D:$D,0))) -> 0 | L1357: 1092
A1358: PEF | B1358: 45444 | C1358: 55153 | D1358: Evolver Fund II Ky | E1358: Non-UCITS | F1358: Closed-end | G1358: Buy-out fund | H1358: Evolver Equity Ab | I1358: Not found | J1358: Continues | K1358: =IF($J1358="Continues",DATEDIF($B1358,TODAY(),"Y"),INDEX('Lopettaneet 2013->'!$L:$L,MATCH($D1358,'Lopettaneet 2013->'!$D:$D,0))) -> 0 | L1358: 1093
A1359: PEF | B1359: 45444 | C1359: 55153 | D1359: Eteläpohjalainen kasvurahasto Ky | E1359: Non-UCITS | F1359: Closed-end | G1359: Venture Capital fund | H1359: Redstone Nordics Oy | I1359: Not found | J1359: Continues | K1359: =IF($J1359="Continues",DATEDIF($B1359,TODAY(),"Y"),INDEX('Lopettaneet 2013->'!$L:$L,MATCH($D1359,'Lopettaneet 2013->'!$D:$D,0))) -> 0 | L1359: 1094
A1360: IVF | B1360: 45444 | C1360: 55153 | D1360: Erikoissijoitusrahasto CapMan Growth Equity Fund III Feeder | E1360: Non-UCITS | F1360: Open-end | G1360: Stock fund | H1360: CapMan | I1360: Not found | J1360: Continues | K1360: =IF($J1360="Continues",DATEDIF($B1360,TODAY(),"Y"),INDEX('Lopettaneet 2013->'!$L:$L,MATCH($D1360,'Lopettaneet 2013->'!$D:$D,0))) -> 0 | L1360: 1095
A1361: IVF | B1361: 45413 | C1361: 55153 | D1361: Placeringsfond Nordea Norge Pluss | E1361: UCITS | F1361: Open-end | G1361: Stock fund | H1361: Nordea | I1361: Not found | J1361: Continues | K1361: =IF($J1361="Continues",DATEDIF($B1361,TODAY(),"Y"),INDEX('Lopettaneet 2013->'!$L:$L,MATCH($D1361,'Lopettaneet 2013->'!$D:$D,0))) -> 1 | L1361: 1096
A1362: IVF | B1362: 45413 | C1362: 55153 | D1362: Placeringsfond Nordea Kort Obligasjon Pluss | E1362: UCITS | F1362: Open-end | G1362: Bond fund | H1362: Nordea | I1362: Not found | J1362: Continues | K1362: =IF($J1362="Continues",DATEDIF($B1362,TODAY(),"Y"),INDEX('Lopettaneet 2013->'!$L:$L,MATCH($D1362,'Lopettaneet 2013->'!$D:$D,0))) -> 1 | L1362: 1097
A1363: IVF | B1363: 45413 | C1363: 55153 | D1363: Placeringsfond Nordea FRN Kreditt | E1363: UCITS | F1363: Open-end | G1363: Bond fund | H1363: Nordea | I1363: Not found | J1363: Continues | K1363: =IF($J1363="Continues",DATEDIF($B1363,TODAY(),"Y"),INDEX('Lopettaneet 2013->'!$L:$L,MATCH($D1363,'Lopettaneet 2013->'!$D:$D,0))) -> 1 | L1363: 1098
A1364: IVF | B1364: 45413 | C1364: 55153 | D1364: Placeringsfond Nordea Obligasjon II | E1364: UCITS | F1364: Open-end | G1364: Bond fund | H1364: Nordea | I1364: Not found | J1364: Continues | K1364: =IF($J1364="Continues",DATEDIF($B1364,TODAY(),"Y"),INDEX('Lopettaneet 2013->'!$L:$L,MATCH($D1364,'Lopettaneet 2013->'!$D:$D,0))) -> 1 | L1364: 1099
A1365: IVF | B1365: 45413 | C1365: 55153 | D1365: Placeringsfond Nordea Obligasjon III | E1365: UCITS | F1365: Open-end | G1365: Bond fund | H1365: Nordea | I1365: Not found | J1365: Continues | K1365: =IF($J1365="Continues",DATEDIF($B1365,TODAY(),"Y"),INDEX('Lopettaneet 2013->'!$L:$L,MATCH($D1365,'Lopettaneet 2013->'!$D:$D,0))) -> 1 | L1365: 1100
A1366: IVF | B1366: 45444 | C1366: 55153 | D1366: OP-Alternative Credit II -erikoissijoitusrahasto | E1366: Non-UCITS | F1366: Open-end | G1366: Bond fund | H1366: Osuuspankki | I1366: Not found | J1366: Continues | K1366: =IF($J1366="Continues",DATEDIF($B1366,TODAY(),"Y"),INDEX('Lopettaneet 2013->'!$L:$L,MATCH($D1366,'Lopettaneet 2013->'!$D:$D,0))) -> 0 | L1366: 1101
A1367: PEF | B1367: 45444 | C1367: 55153 | D1367: Ethos Residential Opportunities I Ky | E1367: Non-UCITS | F1367: Closed-end | G1367: Real-estate fund | H1367: Ethos Capital Oy | I1367: Not found | J1367: Continues | K1367: =IF($J1367="Continues",DATEDIF($B1367,TODAY(),"Y"),INDEX('Lopettaneet 2013->'!$L:$L,MATCH($D1367,'Lopettaneet 2013->'!$D:$D,0))) -> 0 | L1367: 1102
A1368: IVF | B1368: 45413 | C1368: 55153 | D1368: S-Pankki European Private Credit Erikoissijoitusrahasto | E1368: Non-UCITS | F1368: Open-end | G1368: Other fund | H1368: S-Pankki | I1368: Not found | J1368: Continues | K1368: =IF($J1368="Continues",DATEDIF($B1368,TODAY(),"Y"),INDEX('Lopettaneet 2013->'!$L:$L,MATCH($D1368,'Lopettaneet 2013->'!$D:$D,0))) -> 1 | L1368: 1103
... A1371: IVF | B1371: 45413 | C1371: 55153 | D1371: OP-Kestävä Yrityslaina -sijoitusrahasto | E1371: UCITS | F1371: Open-end | G1371: Bond fund | H1371: Osuuspankki | I1371: Not found | J1371: Continues | K1371: =IF($J1371="Continues",DATEDIF($B1371,TODAY(),"Y"),INDEX('Lopettaneet 2013->'!$L:$L,MATCH($D1371,'Lopettaneet 2013->'!$D:$D,0))) -> 1 | L1371: 1106
A1372: IVF | B1372: 39783 | C1372: 45443 | D1372: Sijoitusrahasto LähiTapiola Kuluttaja ESG | E1372: UCITS | F1372: Open-end | G1372: Stock fund | H1372: Lähitapiola | I1372: =IFERROR(INDEX([2]Sheet1!$B:$B,MATCH($D1372,[2]Sheet1!$A:$A,0)),"Not found") -> Retail | J1372: Merged | K1372: =IF($I1372="Continues",DATEDIF($B1372,TODAY(),"Y"),DATEDIF($B1372,$C1372,"Y")) -> 15 | L1372: 1107
A1373: IVF | B1373: 39783 | C1373: 45443 | D1373: Sijoitusrahasto LähiTapiola Kuluttaja ESG | E1373: UCITS | F1373: Open-end | G1373: Stock fund | H1373: Lähitapiola | I1373: =IFERROR(INDEX([2]Sheet1!$B:$B,MATCH($D1373,[2]Sheet1!$A:$A,0)),"Not found") -> Retail | J1373: Merged | K1373: =IF($I1373="Continues",DATEDIF($B1373,TODAY(),"Y"),DATEDIF($B1373,$C1373,"Y")) -> 15 | L1373: 1108
A1374: IVF | B1374: 39783 | C1374: 45443 | D1374: Sijoitusrahasto LähiTapiola Kuluttaja ESG | E1374: UCITS | F1374: Open-end | G1374: Stock fund | H1374: Lähitapiola | I1374: =IFERROR(INDEX([2]Sheet1!$B:$B,MATCH($D1374,[2]Sheet1!$A:$A,0)),"Not found") -> Retail | J1374: Merged | K1374: =IF($I1374="Continues",DATEDIF($B1374,TODAY(),"Y"),DATEDIF($B1374,$C1374,"Y")) -> 15 | L1374: 1109
A1375: IVF | B1375: 39783 | C1375: 45473 | D1375: Sijoitusrahasto Nordea Aasialaiset Tähdet | E1375: UCITS | F1375: Open-end | G1375: Stock fund | H1375: Nordea | I1375: =IFERROR(INDEX([2]Sheet1!$B:$B,MATCH($D1375,[2]Sheet1!$A:$A,0)),"Not found") -> Retail | J1375: Closed | K1375: =IF($I1375="Continues",DATEDIF($B1375,TODAY(),"Y"),DATEDIF($B1375,$C1375,"Y")) -> 15 | L1375: 1110
A1376: IVF | B1376: 40940 | C1376: 45443 | D1376: Erikoissijoitusrahasto Aktia Rahastoyhtiö Oy Vakaa Korko | E1376: Non-UCITS | F1376: Open-end | G1376: Bond fund | H1376: Aktia Rahastoyhtiö Oy | I1376: =IFERROR(INDEX([2]Sheet1!$B:$B,MATCH($D1376,[2]Sheet1!$A:$A,0)),"Not found") -> Not found | J1376: Merged | K1376: =IF($I1376="Continues",DATEDIF($B1376,TODAY(),"Y"),DATEDIF($B1376,$C1376,"Y")) -> 12 | L1376: 1111
A1377: IVF | B1377: 40940 | C1377: 45443 | D1377: Erikoissijoitusrahasto Aktia Rahastoyhtiö Oy Vakaa Korko | E1377: Non-UCITS | F1377: Open-end | G1377: Bond fund | H1377: Aktia Rahastoyhtiö Oy | I1377: =IFERROR(INDEX([2]Sheet1!$B:$B,MATCH($D1377,[2]Sheet1!$A:$A,0)),"Not found") -> Not found | J1377: Merged | K1377: =IF($I1377="Continues",DATEDIF($B1377,TODAY(),"Y"),DATEDIF($B1377,$C1377,"Y")) -> 12 | L1377: 1112
A1378: IVF | B1378: 41214 | C1378: 45443 | D1378: Sijoitusrahasto Nordea Private Banking Kort Obligasjon Pluss | E1378: UCITS | F1378: Open-end | G1378: Bond fund | H1378: Nordea | I1378: =IFERROR(INDEX([2]Sheet1!$B:$B,MATCH($D1378,[2]Sheet1!$A:$A,0)),"Not found") -> Retail | J1378: Merged | K1378: =IF($I1378="Continues",DATEDIF($B1378,TODAY(),"Y"),DATEDIF($B1378,$C1378,"Y")) -> 11 | L1378: 1113
A1379: IVF | B1379: 41214 | C1379: 45443 | D1379: Sijoitusrahasto Nordea Private Banking Obligasjon | E1379: UCITS | F1379: Open-end | G1379: Bond fund | H1379: Nordea | I1379: =IFERROR(INDEX([2]Sheet1!$B:$B,MATCH($D1379,[2]Sheet1!$A:$A,0)),"Not found") -> Retail | J1379: Merged | K1379: =IF($I1379="Continues",DATEDIF($B1379,TODAY(),"Y"),DATEDIF($B1379,$C1379,"Y")) -> 11 | L1379: 1114
A1380: IVF | B1380: 41244 | C1380: 45412 | D1380: Sijoitusrahasto Evli Globaali Korko | E1380: UCITS | F1380: Open-end | G1380: Bond fund | H1380: Evli | I1380: =IFERROR(INDEX([2]Sheet1!$B:$B,MATCH($D1380,[2]Sheet1!$A:$A,0)),"Not found") -> Retail | J1380: Merged | K1380: =IF($I1380="Continues",DATEDIF($B1380,TODAY(),"Y"),DATEDIF($B1380,$C1380,"Y")) -> 11 | L1380: 1115
A1381: IVF | B1381: 42186 | C1381: 45443 | D1381: Specialplaceringsfonden Aktia Rahastoyhtiö Oy SLS | E1381: Non-UCITS | F1381: Open-end | G1381: Stock fund | H1381: Aktia Rahastoyhtiö Oy | I1381: =IFERROR(INDEX([2]Sheet1!$B:$B,MATCH($D1381,[2]Sheet1!$A:$A,0)),"Not found") -> Not found | J1381: Closed | K1381: =IF($I1381="Continues",DATEDIF($B1381,TODAY(),"Y"),DATEDIF($B1381,$C1381,"Y")) -> 8 | L1381: 1116
A1382: PEF | B1382: 42614 | C1382: 45473 | D1382: Epiqus Kotouttaminen I Ky | E1382: Non-UCITS | F1382: Closed-end | G1382: Other fund | H1382: Epiqus | I1382: =IFERROR(INDEX([2]Sheet1!$B:$B,MATCH($D1382,[2]Sheet1!$A:$A,0)),"Not found") -> Non-Retail | J1382: Closed | K1382: =IF($I1382="Continues",DATEDIF($B1382,TODAY(),"Y"),DATEDIF($B1382,$C1382,"Y")) -> 7 | L1382: 1117
A1383: PEF | B1383: 43800 | C1383: 45473 | D1383: Epiqus Kotouttaminen Holding I Ky | E1383: Non-UCITS | F1383: Closed-end | G1383: Other fund | H1383: Epiqus | I1383: =IFERROR(INDEX([2]Sheet1!$B:$B,MATCH($D1383,[2]Sheet1!$A:$A,0)),"Not found") -> Non-Retail | J1383: Closed | K1383: =IF($I1383="Continues",DATEDIF($B1383,TODAY(),"Y"),DATEDIF($B1383,$C1383,"Y")) -> 4 | L1383: 1118
A1384: IVF | B1384: 44378 | C1384: 45412 | D1384: GRIT SLS Erikoissijoitusrahasto | E1384: Non-UCITS | F1384: Open-end | G1384: Stock fund | H1384: GRIT Rahastoyhtiö Oy | I1384: =IFERROR(INDEX([2]Sheet1!$B:$B,MATCH($D1384,[2]Sheet1!$A:$A,0)),"Not found") -> Non-Retail | J1384: Closed | K1384: =IF($I1384="Continues",DATEDIF($B1384,TODAY(),"Y"),DATEDIF($B1384,$C1384,"Y")) -> 2 | L1384: 1119
...

Sheet Aloittaneet 2013->
A1: Kysely | B1: RaportoinninAloitusPvm | C1: RaportoinninLopetusPvm | D1: Raportoija | E1: RaportoijanRahastotunnus | F1: Y_tunnus | G1: UCITS_erikoissijoitusrahastotyyppi | H1: Pääomanvaihtelevuus | I1: Rahastotyyppi | J1: Status | K1: Elinaika (y) | L1: Hallinnointiyhtiö | M1: AIF | N1: AIF - retail | O1: AIF - non-retail
A2: PEF | B2: 41974 | C2: 43100 | D2: Oy Wedeco Ab | E2: 15318791#001 | F2: 6798092 | G2: Non-UCITS | H2: Closed-end | I2: Buyout-rahasto | J2: =IF(ISNUMBER(MATCH($D2,'Lopettaneet 2013->'!$D:$D,0)),INDEX('Lopettaneet 2013->'!$K:$K,MATCH($D2,'Lopettaneet 2013->'!$D:$D,0)),"Continues") -> Closed | K2: =IF($J2="Continues",DATEDIF($B2,TODAY(),"Y"),INDEX('Lopettaneet 2013->'!$L:$L,MATCH($D2,'Lopettaneet 2013->'!$D:$D,0))) -> 3 | L2: =IFERROR(INDEX('[1]30.06.2024'!$H:$H,MATCH($E2,'[1]30.06.2024'!$B:$B,0)),"Not found") -> Not found | M2: =IFERROR(INDEX([2]Sheet1!$B:$B,MATCH($D2,[2]Sheet1!$A:$A,0)),"Not found") -> Not found | N2: =IF($M2="Retail",1,0) -> 0 | O2: =IF($M2="Non-Retail",1,0) -> 0
A3: PEF | B3: 41974 | C3: 42735 | D3: Finnventure Rahasto V Ky | E3: 07490276#006 | F3: 15657523 | G3: Non-UCITS | H3: Closed-end | I3: Buyout-rahasto | J3: =IF(ISNUMBER(MATCH($D3,'Lopettaneet 2013->'!$D:$D,0)),INDEX('Lopettaneet 2013->'!$K:$K,MATCH($D3,'Lopettaneet 2013->'!$D:$D,0)),"Continues") -> Closed | K3: =IF($J3="Continues",DATEDIF($B3,TODAY(),"Y"),INDEX('Lopettaneet 2013->'!$L:$L,MATCH($D3,'Lopettaneet 2013->'!$D:$D,0))) -> 2 | L3: =IFERROR(INDEX('[1]30.06.2024'!$H:$H,MATCH($E3,'[1]30.06.2024'!$B:$B,0)),"Not found") -> Not found | M3: =IFERROR(INDEX([2]Sheet1!$B:$B,MATCH($D3,[2]Sheet1!$A:$A,0)),"Not found") -> Not found | N3: =IF($M3="Retail",1,0) -> 0 | O3: =IF($M3="Non-Retail",1,0) -> 0
A4: PEF | B4: 41974 | C4: 42369 | D4: Maneq Fund 2002 Ky | E4: 19011500#009 | F4: 17285698 | G4: Non-UCITS | H4: Closed-end | I4: Buyout-rahasto | J4: =IF(ISNUMBER(MATCH($D4,'Lopettaneet 2013->'!$D:$D,0)),INDEX('Lopettaneet 2013->'!$K:$K,MATCH($D4,'Lopettaneet 2013->'!$D:$D,0)),"Continues") -> Closed | K4: =IF($J4="Continues",DATEDIF($B4,TODAY(),"Y"),INDEX('Lopettaneet 2013->'!$L:$L,MATCH($D4,'Lopettaneet 2013->'!$D:$D,0))) -> 1 | L4: =IFERROR(INDEX('[1]30.06.2024'!$H:$H,MATCH($E4,'[1]30.06.2024'!$B:$B,0)),"Not found") -> Not found | M4: =IFERROR(INDEX([2]Sheet1!$B:$B,MATCH($D4,[2]Sheet1!$A:$A,0)),"Not found") -> Not found | N4: =IF($M4="Retail",1,0) -> 0 | O4: =IF($M4="Non-Retail",1,0) -> 0
A5: PEF | B5: 41974 | C5: 43738 | D5: Finnmezzanine Rahasto III A Ky | E5: 07490276#008 | F5: 16020110 | G5: Non-UCITS | H5: Closed-end | I5: Buyout-rahasto | J5: =IF(ISNUMBER(MATCH($D5,'Lopettaneet 2013->'!$D:$D,0)),INDEX('Lopettaneet 2013->'!$K:$K,MATCH($D5,'Lopettaneet 2013->'!$D:$D,0)),"Continues") -> Closed | K5: =IF($J5="Continues",DATEDIF($B5,TODAY(),"Y"),INDEX('Lopettaneet 2013->'!$L:$L,MATCH($D5,'Lopettaneet 2013->'!$D:$D,0))) -> 4 | L5: =IFERROR(INDEX('[1]30.06.2024'!$H:$H,MATCH($E5,'[1]30.06.2024'!$B:$B,0)),"Not found") -> Not found | M5: =IFERROR(INDEX([2]Sheet1!$B:$B,MATCH($D5,[2]Sheet1!$A:$A,0)),"Not found") -> Not found | N5: =IF($M5="Retail",1,0) -> 0 | O5: =IF($M5="Non-Retail",1,0) -> 0
A6: PEF | B6: 41974 | C6: 42369 | D6: Finnmezzanine Rahasto III C Ky | E6: 07490276#011 | F6: 16069002 | G6: Non-UCITS | H6: Closed-end | I6: Buyout-rahasto | J6: =IF(ISNUMBER(MATCH($D6,'Lopettaneet 2013->'!$D:$D,0)),INDEX('Lopettaneet 2013->'!$K:$K,MATCH($D6,'Lopettaneet 2013->'!$D:$D,0)),"Continues") -> Closed | K6: =IF($J6="Continues",DATEDIF($B6,TODAY(),"Y"),INDEX('Lopettaneet 2013->'!$L:$L,MATCH($D6,'Lopettaneet 2013->'!$D:$D,0))) -> 1 | L6: =IFERROR(INDEX('[1]30.06.2024'!$H:$H,MATCH($E6,'[1]30.06.2024'!$B:$B,0)),"Not found") -> Not found | M6: =IFERROR(INDEX([2]Sheet1!$B:$B,MATCH($D6,[2]Sheet1!$A:$A,0)),"Not found") -> Not found | N6: =IF($M6="Retail",1,0) -> 0 | O6: =IF($M6="Non-Retail",1,0) -> 0
A7: PEF | B7: 41974 | C7: 43738 | D7: Finnmezzanine Rahasto III B Ky | E7: 07490276#009 | F7: 16020137 | G7: Non-UCITS | H7: Closed-end | I7: Buyout-rahasto | J7: =IF(ISNUMBER(MATCH($D7,'Lopettaneet 2013->'!$D:$D,0)),INDEX('Lopettaneet 2013->'!$K:$K,MATCH($D7,'Lopettaneet 2013->'!$D:$D,0)),"Continues") -> Closed | K7: =IF($J7="Continues",DATEDIF($B7,TODAY(),"Y"),INDEX('Lopettaneet 2013->'!$L:$L,MATCH($D7,'Lopettaneet 2013->'!$D:$D,0))) -> 4 | L7: =IFERROR(INDEX('[1]30.06.2024'!$H:$H,MATCH($E7,'[1]30.06.2024'!$B:$B,0)),"Not found") -> Not found | M7: =IFERROR(INDEX([2]Sheet1!$B:$B,MATCH($D7,[2]Sheet1!$A:$A,0)),"Not found") -> Not found | N7: =IF($M7="Retail",1,0) -> 0 | O7: =IF($M7="Non-Retail",1,0) -> 0
A8: PEF | B8: 41974 | C8: 44196 | D8: CapMan Real Estate I Ky | E8: 07491762#001 | F8: 19720366 | G8: Non-UCITS | H8: Closed-end | I8: Kiinteistörahasto | J8: =IF(ISNUMBER(MATCH($D8,'Lopettaneet 2013->'!$D:$D,0)),INDEX('Lopettaneet 2013->'!$K:$K,MATCH($D8,'Lopettaneet 2013->'!$D:$D,0)),"Continues") -> Closed | K8: =IF($J8="Continues",DATEDIF($B8,TODAY(),"Y"),INDEX('Lopettaneet 2013->'!$L:$L,MATCH($D8,'Lopettaneet 2013->'!$D:$D,0))) -> 6 | L8: =IFERROR(INDEX('[1]30.06.2024'!$H:$H,MATCH($E8,'[1]30.06.2024'!$B:$B,0)),"Not found") -> Not found | M8: =IFERROR(INDEX([2]Sheet1!$B:$B,MATCH($D8,[2]Sheet1!$A:$A,0)),"Not found") -> Not found | N8: =IF($M8="Retail",1,0) -> 0 | O8: =IF($M8="Non-Retail",1,0) -> 0
A9: IVF | B9: 43466 | C9: 55153 | D9: OP-Euro -sijoitusrahasto | E9: 07439622#016 | F9: 11024008 | G9: UCITS | H9: Open-end | I9: Korkorahasto | J9: =IF(ISNUMBER(MATCH($D9,'Lopettaneet 2013->'!$D:$D,0)),INDEX('Lopettaneet 2013->'!$K:$K,MATCH($D9,'Lopettaneet 2013->'!$D:$D,0)),"Continues") -> Closed | K9: =IF($J9="Continues",DATEDIF($B9,TODAY(),"Y"),INDEX('Lopettaneet 2013->'!$L:$L,MATCH($D9,'Lopettaneet 2013->'!$D:$D,0))) -> 10 | L9: =IFERROR(INDEX('[1]30.06.2024'!$H:$H,MATCH($E9,'[1]30.06.2024'!$B:$B,0)),"Not found") -> OP-Rahastoyhtiö Oy | M9: =IFERROR(INDEX([2]Sheet1!$B:$B,MATCH($D9,[2]Sheet1!$A:$A,0)),"Not found") -> Retail | N9: =IF($M9="Retail",1,0) -> 1 | O9: =IF($M9="Non-Retail",1,0) -> 0
A10: IVF | B10: 43466 | C10: 55153 | D10: S-Pankki Lyhyt Korko Sijoitusrahasto | E10: 09791339#004 | F10: 20667232 | G10: UCITS | H10: Open-end | I10: Korkorahasto | J10: =IF(ISNUMBER(MATCH($D10,'Lopettaneet 2013->'!$D:$D,0)),INDEX('Lopettaneet 2013->'!$K:$K,MATCH($D10,'Lopettaneet 2013->'!$D:$D,0)),"Continues") -> Closed | K10: =IF($J10="Continues",DATEDIF($B10,TODAY(),"Y"),INDEX('Lopettaneet 2013->'!$L:$L,MATCH($D10,'Lopettaneet 2013->'!$D:$D,0))) -> 6 | L10: =IFERROR(INDEX('[1]30.06.2024'!$H:$H,MATCH($E10,'[1]30.06.2024'!$B:$B,0)),"Not found") -> S-Pankki Rahastoyhtiö Oy | M10: =IFERROR(INDEX([2]Sheet1!$B:$B,MATCH($D10,[2]Sheet1!$A:$A,0)),"Not found") -> Retail | N10: =IF($M10="Retail",1,0) -> 1 | O10: =IF($M10="Non-Retail",1,0) -> 0
A11: PEF | B11: 41974 | C11: 44469 | D11: Veraventure Oy | E11: 08425222#002 | F11: 8425222 | G11: Non-UCITS | H11: Closed-end | I11: Venture Capital -rahasto | J11: =IF(ISNUMBER(MATCH($D11,'Lopettaneet 2013->'!$D:$D,0)),INDEX('Lopettaneet 2013->'!$K:$K,MATCH($D11,'Lopettaneet 2013->'!$D:$D,0)),"Continues") -> Closed | K11: =IF($J11="Continues",DATEDIF($B11,TODAY(),"Y"),INDEX('Lopettaneet 2013->'!$L:$L,MATCH($D11,'Lopettaneet 2013->'!$D:$D,0))) -> 6 | L11: =IFERROR(INDEX('[1]30.06.2024'!$H:$H,MATCH($E11,'[1]30.06.2024'!$B:$B,0)),"Not found") -> Not found | M11: =IFERROR(INDEX([2]Sheet1!$B:$B,MATCH($D11,[2]Sheet1!$A:$A,0)),"Not found") -> Not found | N11: =IF($M11="Retail",1,0) -> 0 | O11: =IF($M11="Non-Retail",1,0) -> 0
A12: PEF | B12: 41974 | C12: 43100 | D12: Aloitusrahasto Vera Oy | E12: 08425222#001 | F12: 8425142 | G12: Non-UCITS | H12: Closed-end | I12: Venture Capital -rahasto | J12: =IF(ISNUMBER(MATCH($D12,'Lopettaneet 2013->'!$D:$D,0)),INDEX('Lopettaneet 2013->'!$K:$K,MATCH($D12,'Lopettaneet 2013->'!$D:$D,0)),"Continues") -> Closed | K12: =IF($J12="Continues",DATEDIF($B12,TODAY(),"Y"),INDEX('Lopettaneet 2013->'!$L:$L,MATCH($D12,'Lopettaneet 2013->'!$D:$D,0))) -> 3 | L12: =IFERROR(INDEX('[1]30.06.2024'!$H:$H,MATCH($E12,'[1]30.06.2024'!$B:$B,0)),"Not found") -> Not found | M12: =IFERROR(INDEX([2]Sheet1!$B:$B,MATCH($D12,[2]Sheet1!$A:$A,0)),"Not found") -> Not found | N12: =IF($M12="Retail",1,0) -> 0 | O12: =IF($M12="Non-Retail",1,0) -> 0
A13: IVF | B13: 43466 | C13: 55153 | D13: Sijoitusrahasto eQ Lyhyt Korko | E13: 07360527#007 | F13: 18001415 | G13: UCITS | H13: Open-end | I13: Korkorahasto | J13: =IF(ISNUMBER(MATCH($D13,'Lopettaneet 2013->'!$D:$D,0)),INDEX('Lopettaneet 2013->'!$K:$K,MATCH($D13,'Lopettaneet 2013->'!$D:$D,0)),"Continues") -> Closed | K13: =IF($J13="Continues",DATEDIF($B13,TODAY(),"Y"),INDEX('Lopettaneet 2013->'!$L:$L,MATCH($D13,'Lopettaneet 2013->'!$D:$D,0))) -> 10 | L13: =IFERROR(INDEX('[1]30.06.2024'!$H:$H,MATCH($E13,'[1]30.06.2024'!$B:$B,0)),"Not found") -> eQ Rahastoyhtiö Oy | M13: =IFERROR(INDEX([2]Sheet1!$B:$B,MATCH($D13,[2]Sheet1!$A:$A,0)),"Not found") -> Retail | N13: =IF($M13="Retail",1,0) -> 1 | O13: =IF($M13="Non-Retail",1,0) -> 0
... A292: PEF | B292: 41974 | C292: 42460 | D292: EPI Baltic I Oy | E292: 19331184#002 | F292: 19488085 | G292: Non-UCITS | H292: Closed-end | I292: Kiinteistörahasto | J292: =IF(ISNUMBER(MATCH($D292,'Lopettaneet 2013->'!$D:$D,0)),INDEX('Lopettaneet 2013->'!$K:$K,MATCH($D292,'Lopettaneet 2013->'!$D:$D,0)),"Continues") -> Closed | K292: =IF($J292="Continues",DATEDIF($B292,TODAY(),"Y"),INDEX('Lopettaneet 2013->'!$L:$L,MATCH($D292,'Lopettaneet 2013->'!$D:$D,0))) -> 1 | L292: =IFERROR(INDEX('[1]30.06.2024'!$H:$H,MATCH($E292,'[1]30.06.2024'!$B:$B,0)),"Not found") -> Not found | M292: =IFERROR(INDEX([2]Sheet1!$B:$B,MATCH($D292,[2]Sheet1!$A:$A,0)),"Not found") -> Not found | N292: =IF($M292="Retail",1,0) -> 0 | O292: =IF($M292="Non-Retail",1,0) -> 0
A293: PEF | B293: 41974 | C293: 43100 | D293: MultiFire | E293: 19208258#001 | F293: NULL | G293: Non-UCITS | H293: Closed-end | I293: Hedge-rahasto | J293: =IF(ISNUMBER(MATCH($D293,'Lopettaneet 2013->'!$D:$D,0)),INDEX('Lopettaneet 2013->'!$K:$K,MATCH($D293,'Lopettaneet 2013->'!$D:$D,0)),"Continues") -> Closed | K293: =IF($J293="Continues",DATEDIF($B293,TODAY(),"Y"),INDEX('Lopettaneet 2013->'!$L:$L,MATCH($D293,'Lopettaneet 2013->'!$D:$D,0))) -> 3 | L293: =IFERROR(INDEX('[1]30.06.2024'!$H:$H,MATCH($E293,'[1]30.06.2024'!$B:$B,0)),"Not found") -> Not found | M293: =IFERROR(INDEX([2]Sheet1!$B:$B,MATCH($D293,[2]Sheet1!$A:$A,0)),"Not found") -> Not found | N293: =IF($M293="Retail",1,0) -> 0 | O293: =IF($M293="Non-Retail",1,0) -> 0
A294: PEF | B294: 41974 | C294: 43373 | D294: Maneq Fund 2004 Ky | E294: 19011500#008 | F294: 18634351 | G294: Non-UCITS | H294: Closed-end | I294: Buyout-rahasto | J294: =IF(ISNUMBER(MATCH($D294,'Lopettaneet 2013->'!$D:$D,0)),INDEX('Lopettaneet 2013->'!$K:$K,MATCH($D294,'Lopettaneet 2013->'!$D:$D,0)),"Continues") -> Closed | K294: =IF($J294="Continues",DATEDIF($B294,TODAY(),"Y"),INDEX('Lopettaneet 2013->'!$L:$L,MATCH($D294,'Lopettaneet 2013->'!$D:$D,0))) -> 3 | L294: =IFERROR(INDEX('[1]30.06.2024'!$H:$H,MATCH($E294,'[1]30.06.2024'!$B:$B,0)),"Not found") -> Not found | M294: =IFERROR(INDEX([2]Sheet1!$B:$B,MATCH($D294,[2]Sheet1!$A:$A,0)),"Not found") -> Not found | N294: =IF($M294="Retail",1,0) -> 0 | O294: =IF($M294="Non-Retail",1,0) -> 0
A295: PEF | B295: 41974 | C295: 55153 | D295: TKPM Asuntorahasto I Ky | E295: 18212730#001 | F295: 25129345 | G295: Non-UCITS | H295: Closed-end | I295: Kiinteistörahasto | J295: =IF(ISNUMBER(MATCH($D295,'Lopettaneet 2013->'!$D:$D,0)),INDEX('Lopettaneet 2013->'!$K:$K,MATCH($D295,'Lopettaneet 2013->'!$D:$D,0)),"Continues") -> Continues | K295: =IF($J295="Continues",DATEDIF($B295,TODAY(),"Y"),INDEX('Lopettaneet 2013->'!$L:$L,MATCH($D295,'Lopettaneet 2013->'!$D:$D,0))) -> 10 | L295: =IFERROR(INDEX('[1]30.06.2024'!$H:$H,MATCH($E295,'[1]30.06.2024'!$B:$B,0)),"Not found") -> Taitokaari Property Management Oy | M295: =IFERROR(INDEX([2]Sheet1!$B:$B,MATCH($D295,[2]Sheet1!$A:$A,0)),"Not found") -> Non-Retail | N295: =IF($M295="Retail",1,0) -> 0 | O295: =IF($M295="Non-Retail",1,0) -> 1
A296: PEF | B296: 41974 | C296: 55153 | D296: LähiTapiola Asuntorahasto Prime Feeder Oy | E296: 16172050#001 | F296: 25038101 | G296: Non-UCITS | H296: Closed-end | I296: Kiinteistörahasto | J296: =IF(ISNUMBER(MATCH($D296,'Lopettaneet 2013->'!$D:$D,0)),INDEX('Lopettaneet 2013->'!$K:$K,MATCH($D296,'Lopettaneet 2013->'!$D:$D,0)),"Continues") -> Continues | K296: =IF($J296="Continues",DATEDIF($B296,TODAY(),"Y"),INDEX('Lopettaneet 2013->'!$L:$L,MATCH($D296,'Lopettaneet 2013->'!$D:$D,0))) -> 10 | L296: =IFERROR(INDEX('[1]30.06.2024'!$H:$H,MATCH($E296,'[1]30.06.2024'!$B:$B,0)),"Not found") -> LähiTapiola Vaihtoehtorahastot Oy | M296: =IFERROR(INDEX([2]Sheet1!$B:$B,MATCH($D296,[2]Sheet1!$A:$A,0)),"Not found") -> Non-Retail | N296: =IF($M296="Retail",1,0) -> 0 | O296: =IF($M296="Non-Retail",1,0) -> 1
A297: PEF | B297: 41974 | C297: 43646 | D297: TuuliTapiola Ky | E297: 16172050#002 | F297: 20748876 | G297: Non-UCITS | H297: Closed-end | I297: Venture Capital -rahasto | J297: =IF(ISNUMBER(MATCH($D297,'Lopettaneet 2013->'!$D:$D,0)),INDEX('Lopettaneet 2013->'!$K:$K,MATCH($D297,'Lopettaneet 2013->'!$D:$D,0)),"Continues") -> Closed | K297: =IF($J297="Continues",DATEDIF($B297,TODAY(),"Y"),INDEX('Lopettaneet 2013->'!$L:$L,MATCH($D297,'Lopettaneet 2013->'!$D:$D,0))) -> 4 | L297: =IFERROR(INDEX('[1]30.06.2024'!$H:$H,MATCH($E297,'[1]30.06.2024'!$B:$B,0)),"Not found") -> Not found | M297: =IFERROR(INDEX([2]Sheet1!$B:$B,MATCH($D297,[2]Sheet1!$A:$A,0)),"Not found") -> Not found | N297: =IF($M297="Retail",1,0) -> 0 | O297: =IF($M297="Non-Retail",1,0) -> 0
A298: PEF | B298: 41974 | C298: 55153 | D298: LähiTapiola Asuntorahasto Prime Ky | E298: 16172050#003 | F298: 25317098 | G298: Non-UCITS | H298: Closed-end | I298: Kiinteistörahasto | J298: =IF(ISNUMBER(MATCH($D298,'Lopettaneet 2013->'!$D:$D,0)),INDEX('Lopettaneet 2013->'!$K:$K,MATCH($D298,'Lopettaneet 2013->'!$D:$D,0)),"Continues") -> Continues | K298: =IF($J298="Continues",DATEDIF($B298,TODAY(),"Y"),INDEX('Lopettaneet 2013->'!$L:$L,MATCH($D298,'Lopettaneet 2013->'!$D:$D,0))) -> 10 | L298: =IFERROR(INDEX('[1]30.06.2024'!$H:$H,MATCH($E298,'[1]30.06.2024'!$B:$B,0)),"Not found") -> LähiTapiola Vaihtoehtorahastot Oy | M298: =IFERROR(INDEX([2]Sheet1!$B:$B,MATCH($D298,[2]Sheet1!$A:$A,0)),"Not found") -> Non-Retail | N298: =IF($M298="Retail",1,0) -> 0 | O298: =IF($M298="Non-Retail",1,0) -> 1
A299: PEF | B299: 41974 | C299: 42735 | D299: Rival 10 Invest Oy | E299: 16105296#001 | F299: 24297267 | G299: Non-UCITS | H299: Closed-end | I299: Venture Capital -rahasto | J299: =IF(ISNUMBER(MATCH($D299,'Lopettaneet 2013->'!$D:$D,0)),INDEX('Lopettaneet 2013->'!$K:$K,MATCH($D299,'Lopettaneet 2013->'!$D:$D,0)),"Continues") -> Closed | K299: =IF($J299="Continues",DATEDIF($B299,TODAY(),"Y"),INDEX('Lopettaneet 2013->'!$L:$L,MATCH($D299,'Lopettaneet 2013->'!$D:$D,0))) -> 2 | L299: =IFERROR(INDEX('[1]30.06.2024'!$H:$H,MATCH($E299,'[1]30.06.2024'!$B:$B,0)),"Not found") -> Not found | M299: =IFERROR(INDEX([2]Sheet1!$B:$B,MATCH($D299,[2]Sheet1!$A:$A,0)),"Not found") -> Not found | N299: =IF($M299="Retail",1,0) -> 0 | O299: =IF($M299="Non-Retail",1,0) -> 0
A300: PEF | B300: 41974 | C300: 55153 | D300: Selected Private Equity Investment II Ky | E300: 01120872#007 | F300: 23351831 | G300: Non-UCITS | H300: Closed-end | I300: Buyout-rahasto | J300: =IF(ISNUMBER(MATCH($D300,'Lopettaneet 2013->'!$D:$D,0)),INDEX('Lopettaneet 2013->'!$K:$K,MATCH($D300,'Lopettaneet 2013->'!$D:$D,0)),"Continues") -> Continues | K300: =IF($J300="Continues",DATEDIF($B300,TODAY(),"Y"),INDEX('Lopettaneet 2013->'!$L:$L,MATCH($D300,'Lopettaneet 2013->'!$D:$D,0))) -> 10 | L300: =IFERROR(INDEX('[1]30.06.2024'!$H:$H,MATCH($E300,'[1]30.06.2024'!$B:$B,0)),"Not found") -> Access Capital Advisors Finland Oy | M300: =IFERROR(INDEX([2]Sheet1!$B:$B,MATCH($D300,[2]Sheet1!$A:$A,0)),"Not found") -> Non-Retail | N300: =IF($M300="Retail",1,0) -> 0 | O300: =IF($M300="Non-Retail",1,0) -> 1
A301: PEF | B301: 41974 | C301: 42369 | D301: Rival VIII Invest Oy | E301: 16105296#002 | F301: 23591261 | G301: Non-UCITS | H301: Closed-end | I301: Venture Capital -rahasto | J301: =IF(ISNUMBER(MATCH($D301,'Lopettaneet 2013->'!$D:$D,0)),INDEX('Lopettaneet 2013->'!$K:$K,MATCH($D301,'Lopettaneet 2013->'!$D:$D,0)),"Continues") -> Closed | K301: =IF($J301="Continues",DATEDIF($B301,TODAY(),"Y"),INDEX('Lopettaneet 2013->'!$L:$L,MATCH($D301,'Lopettaneet 2013->'!$D:$D,0))) -> 1 | L301: =IFERROR(INDEX('[1]30.06.2024'!$H:$H,MATCH($E301,'[1]30.06.2024'!$B:$B,0)),"Not found") -> Not found | M301: =IFERROR(INDEX([2]Sheet1!$B:$B,MATCH($D301,[2]Sheet1!$A:$A,0)),"Not found") -> Not found | N301: =IF($M301="Retail",1,0) -> 0 | O301: =IF($M301="Non-Retail",1,0) -> 0
A302: PEF | B302: 41974 | C302: 43100 | D302: Rival XIV Invest Oy | E302: 16105296#003 | F302: 25429196 | G302: Non-UCITS | H302: Closed-end | I302: Venture Capital -rahasto | J302: =IF(ISNUMBER(MATCH($D302,'Lopettaneet 2013->'!$D:$D,0)),INDEX('Lopettaneet 2013->'!$K:$K,MATCH($D302,'Lopettaneet 2013->'!$D:$D,0)),"Continues") -> Closed | K302: =IF($J302="Continues",DATEDIF($B302,TODAY(),"Y"),INDEX('Lopettaneet 2013->'!$L:$L,MATCH($D302,'Lopettaneet 2013->'!$D:$D,0))) -> 3 | L302: =IFERROR(INDEX('[1]30.06.2024'!$H:$H,MATCH($E302,'[1]30.06.2024'!$B:$B,0)),"Not found") -> Not found | M302: =IFERROR(INDEX([2]Sheet1!$B:$B,MATCH($D302,[2]Sheet1!$A:$A,0)),"Not found") -> Not found | N302: =IF($M302="Retail",1,0) -> 0 | O302: =IF($M302="Non-Retail",1,0) -> 0
A303: PEF | B303: 41974 | C303: 44742 | D303: Rival XV Invest Oy | E303: 16105296#004 | F303: 25510867 | G303: Non-UCITS | H303: Closed-end | I303: Buyout-rahasto | J303: =IF(ISNUMBER(MATCH($D303,'Lopettaneet 2013->'!$D:$D,0)),INDEX('Lopettaneet 2013->'!$K:$K,MATCH($D303,'Lopettaneet 2013->'!$D:$D,0)),"Continues") -> Closed | K303: =IF($J303="Continues",DATEDIF($B303,TODAY(),"Y"),INDEX('Lopettaneet 2013->'!$L:$L,MATCH($D303,'Lopettaneet 2013->'!$D:$D,0))) -> 7 | L303: =IFERROR(INDEX('[1]30.06.2024'!$H:$H,MATCH($E303,'[1]30.06.2024'!$B:$B,0)),"Not found") -> Not found | M303: =IFERROR(INDEX([2]Sheet1!$B:$B,MATCH($D303,[2]Sheet1!$A:$A,0)),"Not found") -> Not found | N303: =IF($M303="Retail",1,0) -> 0 | O303: =IF($M303="Non-Retail",1,0) -> 0
A304: PEF | B304: 41974 | C304: 43008 | D304: Ursula Invest Oy | E304: 16105296#005 | F304: 20487880 | G304: Non-UCITS | H304: Closed-end | I304: Venture Capital -rahasto | J304: =IF(ISNUMBER(MATCH($D304,'Lopettaneet 2013->'!$D:$D,0)),INDEX('Lopettaneet 2013->'!$K:$K,MATCH($D304,'Lopettaneet 2013->'!$D:$D,0)),"Continues") -> Closed | K304: =IF($J304="Continues",DATEDIF($B304,TODAY(),"Y"),INDEX('Lopettaneet 2013->'!$L:$L,MATCH($D304,'Lopettaneet 2013->'!$D:$D,0))) -> 2 | L304: =IFERROR(INDEX('[1]30.06.2024'!$H:$H,MATCH($E304,'[1]30.06.2024'!$B:$B,0)),"Not found") -> Not found | M304: =IFERROR(INDEX([2]Sheet1!$B:$B,MATCH($D304,[2]Sheet1!$A:$A,0)),"Not found") -> Not found | N304: =IF($M304="Retail",1,0) -> 0 | O304: =IF($M304="Non-Retail",1,0) -> 0
A305: PEF | B305: 41974 | C305: 42369 | D305: Rival IX Invest Oy | E305: 16105296#006 | F305: 24006669 | G305: Non-UCITS | H305: Closed-end | I305: Venture Capital -rahasto | J305: =IF(ISNUMBER(MATCH($D305,'Lopettaneet 2013->'!$D:$D,0)),INDEX('Lopettaneet 2013->'!$K:$K,MATCH($D305,'Lopettaneet 2013->'!$D:$D,0)),"Continues") -> Closed | K305: =IF($J305="Continues",DATEDIF($B305,TODAY(),"Y"),INDEX('Lopettaneet 2013->'!$L:$L,MATCH($D305,'Lopettaneet 2013->'!$D:$D,0))) -> 1 | L305: =IFERROR(INDEX('[1]30.06.2024'!$H:$H,MATCH($E305,'[1]30.06.2024'!$B:$B,0)),"Not found") -> Not found | M305: =IFERROR(INDEX([2]Sheet1!$B:$B,MATCH($D305,[2]Sheet1!$A:$A,0)),"Not found") -> Not found | N305: =IF($M305="Retail",1,0) -> 0 | O305: =IF($M305="Non-Retail",1,0) -> 0
... A359: PEF | B359: 42186 | C359: 42551 | D359: MedTECH Rahasto Pre-Exit Ky | E359: 20831856#002 | F359: 26783525 | G359: Non-UCITS | H359: Closed-end | I359: Venture Capital -rahasto | J359: =IF(ISNUMBER(MATCH($D359,'Lopettaneet 2013->'!$D:$D,0)),INDEX('Lopettaneet 2013->'!$K:$K,MATCH($D359,'Lopettaneet 2013->'!$D:$D,0)),"Continues") -> Closed | K359: =IF($J359="Continues",DATEDIF($B359,TODAY(),"Y"),INDEX('Lopettaneet 2013->'!$L:$L,MATCH($D359,'Lopettaneet 2013->'!$D:$D,0))) -> 0 | L359: =IFERROR(INDEX('[1]30.06.2024'!$H:$H,MATCH($E359,'[1]30.06.2024'!$B:$B,0)),"Not found") -> Not found | M359: =IFERROR(INDEX([2]Sheet1!$B:$B,MATCH($D359,[2]Sheet1!$A:$A,0)),"Not found") -> Not found | N359: =IF($M359="Retail",1,0) -> 0 | O359: =IF($M359="Non-Retail",1,0) -> 0
A360: PEF | B360: 42186 | C360: 42521 | D360: Posse Fund I Ky | E360: 26593748#001 | F360: NULL | G360: Non-UCITS | H360: Closed-end | I360: Venture Capital -rahasto | J360: =IF(ISNUMBER(MATCH($D360,'Lopettaneet 2013->'!$D:$D,0)),INDEX('Lopettaneet 2013->'!$K:$K,MATCH($D360,'Lopettaneet 2013->'!$D:$D,0)),"Continues") -> Closed | K360: =IF($J360="Continues",DATEDIF($B360,TODAY(),"Y"),INDEX('Lopettaneet 2013->'!$L:$L,MATCH($D360,'Lopettaneet 2013->'!$D:$D,0))) -> 0 | L360: =IFERROR(INDEX('[1]30.06.2024'!$H:$H,MATCH($E360,'[1]30.06.2024'!$B:$B,0)),"Not found") -> Not found | M360: =IFERROR(INDEX([2]Sheet1!$B:$B,MATCH($D360,[2]Sheet1!$A:$A,0)),"Not found") -> Not found | N360: =IF($M360="Retail",1,0) -> 0 | O360: =IF($M360="Non-Retail",1,0) -> 0
A361: PEF | B361: 42156 | C361: 55153 | D361: Kasvattajarahasto Ky | E361: 08718295#004 | F361: 26992837 | G361: Non-UCITS | H361: Closed-end | I361: Buyout-rahasto | J361: =IF(ISNUMBER(MATCH($D361,'Lopettaneet 2013->'!$D:$D,0)),INDEX('Lopettaneet 2013->'!$K:$K,MATCH($D361,'Lopettaneet 2013->'!$D:$D,0)),"Continues") -> Continues | K361: =IF($J361="Continues",DATEDIF($B361,TODAY(),"Y"),INDEX('Lopettaneet 2013->'!$L:$L,MATCH($D361,'Lopettaneet 2013->'!$D:$D,0))) -> 9 | L361: =IFERROR(INDEX('[1]30.06.2024'!$H:$H,MATCH($E361,'[1]30.06.2024'!$B:$B,0)),"Not found") -> Aboa Venture Management Oy | M361: =IFERROR(INDEX([2]Sheet1!$B:$B,MATCH($D361,[2]Sheet1!$A:$A,0)),"Not found") -> Non-Retail | N361: =IF($M361="Retail",1,0) -> 0 | O361: =IF($M361="Non-Retail",1,0) -> 1
A362: PEF | B362: 42248 | C362: 55153 | D362: Open Ocean Fund 2015 Ky | E362: 26638993#001 | F362: 27050315 | G362: Non-UCITS | H362: Closed-end | I362: Venture Capital -rahasto | J362: =IF(ISNUMBER(MATCH($D362,'Lopettaneet 2013->'!$D:$D,0)),INDEX('Lopettaneet 2013->'!$K:$K,MATCH($D362,'Lopettaneet 2013->'!$D:$D,0)),"Continues") -> Continues | K362: =IF($J362="Continues",DATEDIF($B362,TODAY(),"Y"),INDEX('Lopettaneet 2013->'!$L:$L,MATCH($D362,'Lopettaneet 2013->'!$D:$D,0))) -> 9 | L362: =IFERROR(INDEX('[1]30.06.2024'!$H:$H,MATCH($E362,'[1]30.06.2024'!$B:$B,0)),"Not found") -> Open Ocean Partners Oy | M362: =IFERROR(INDEX([2]Sheet1!$B:$B,MATCH($D362,[2]Sheet1!$A:$A,0)),"Not found") -> Non-Retail | N362: =IF($M362="Retail",1,0) -> 0 | O362: =IF($M362="Non-Retail",1,0) -> 1
A363: IVF | B363: 42186 | C363: 55153 | D363: Specialplaceringsfonden Aktia SLS | E363: 06725133#040 | F363: 26980107 | G363: Non-UCITS | H363: Open-end | I363: Osakerahasto | J363: =IF(ISNUMBER(MATCH($D363,'Lopettaneet 2013->'!$D:$D,0)),INDEX('Lopettaneet 2013->'!$K:$K,MATCH($D363,'Lopettaneet 2013->'!$D:$D,0)),"Continues") -> Closed | K363: =IF($J363="Continues",DATEDIF($B363,TODAY(),"Y"),INDEX('Lopettaneet 2013->'!$L:$L,MATCH($D363,'Lopettaneet 2013->'!$D:$D,0))) -> 8 | L363: =IFERROR(INDEX('[1]30.06.2024'!$H:$H,MATCH($E363,'[1]30.06.2024'!$B:$B,0)),"Not found") -> Not found | M363: =IFERROR(INDEX([2]Sheet1!$B:$B,MATCH($D363,[2]Sheet1!$A:$A,0)),"Not found") -> Non-Retail | N363: =IF($M363="Retail",1,0) -> 0 | O363: =IF($M363="Non-Retail",1,0) -> 1
A364: PEF | B364: 42217 | C364: 55153 | D364: WasaGroup Fund III Ky | E364: 25416942#002 | F364: 26870493 | G364: Non-UCITS | H364: Closed-end | I364: Kiinteistörahasto | J364: =IF(ISNUMBER(MATCH($D364,'Lopettaneet 2013->'!$D:$D,0)),INDEX('Lopettaneet 2013->'!$K:$K,MATCH($D364,'Lopettaneet 2013->'!$D:$D,0)),"Continues") -> Continues | K364: =IF($J364="Continues",DATEDIF($B364,TODAY(),"Y"),INDEX('Lopettaneet 2013->'!$L:$L,MATCH($D364,'Lopettaneet 2013->'!$D:$D,0))) -> 9 | L364: =IFERROR(INDEX('[1]30.06.2024'!$H:$H,MATCH($E364,'[1]30.06.2024'!$B:$B,0)),"Not found") -> WasaGroup Funds Oy | M364: =IFERROR(INDEX([2]Sheet1!$B:$B,MATCH($D364,[2]Sheet1!$A:$A,0)),"Not found") -> Non-Retail | N364: =IF($M364="Retail",1,0) -> 0 | O364: =IF($M364="Non-Retail",1,0) -> 1
A365: PEF | B365: 42217 | C365: 55153 | D365: WasaGroup Fund II Ky | E365: 25416942#003 | F365: 26870418 | G365: Non-UCITS | H365: Closed-end | I365: Kiinteistörahasto | J365: =IF(ISNUMBER(MATCH($D365,'Lopettaneet 2013->'!$D:$D,0)),INDEX('Lopettaneet 2013->'!$K:$K,MATCH($D365,'Lopettaneet 2013->'!$D:$D,0)),"Continues") -> Continues | K365: =IF($J365="Continues",DATEDIF($B365,TODAY(),"Y"),INDEX('Lopettaneet 2013->'!$L:$L,MATCH($D365,'Lopettaneet 2013->'!$D:$D,0))) -> 9 | L365: =IFERROR(INDEX('[1]30.06.2024'!$H:$H,MATCH($E365,'[1]30.06.2024'!$B:$B,0)),"Not found") -> WasaGroup Funds Oy | M365: =IFERROR(INDEX([2]Sheet1!$B:$B,MATCH($D365,[2]Sheet1!$A:$A,0)),"Not found") -> Non-Retail | N365: =IF($M365="Retail",1,0) -> 0 | O365: =IF($M365="Non-Retail",1,0) -> 1
A366: PEF | B366: 42217 | C366: 55153 | D366: Taaleri Kiinteistökehitys C-Sarja Ky | E366: 22643277#027 | F366: 26975746 | G366: Non-UCITS | H366: Closed-end | I366: Kiinteistörahasto | J366: =IF(ISNUMBER(MATCH($D366,'Lopettaneet 2013->'!$D:$D,0)),INDEX('Lopettaneet 2013->'!$K:$K,MATCH($D366,'Lopettaneet 2013->'!$D:$D,0)),"Continues") -> Continues | K366: =IF($J366="Continues",DATEDIF($B366,TODAY(),"Y"),INDEX('Lopettaneet 2013->'!$L:$L,MATCH($D366,'Lopettaneet 2013->'!$D:$D,0))) -> 9 | L366: =IFERROR(INDEX('[1]30.06.2024'!$H:$H,MATCH($E366,'[1]30.06.2024'!$B:$B,0)),"Not found") -> Taaleri Pääomarahastot Oy | M366: =IFERROR(INDEX([2]Sheet1!$B:$B,MATCH($D366,[2]Sheet1!$A:$A,0)),"Not found") -> Retail | N366: =IF($M366="Retail",1,0) -> 1 | O366: =IF($M366="Non-Retail",1,0) -> 0
A367: IVF | B367: 42248 | C367: 43434 | D367: Ålandsbanken Kort Ränta SEK Placeringsfond | E367: 14713626#028 | F367: 27068806 | G367: UCITS | H367: Open-end | I367: Korkorahasto | J367: =IF(ISNUMBER(MATCH($D367,'Lopettaneet 2013->'!$D:$D,0)),INDEX('Lopettaneet 2013->'!$K:$K,MATCH($D367,'Lopettaneet 2013->'!$D:$D,0)),"Continues") -> Merged | K367: =IF($J367="Continues",DATEDIF($B367,TODAY(),"Y"),INDEX('Lopettaneet 2013->'!$L:$L,MATCH($D367,'Lopettaneet 2013->'!$D:$D,0))) -> 3 | L367: =IFERROR(INDEX('[1]30.06.2024'!$H:$H,MATCH($E367,'[1]30.06.2024'!$B:$B,0)),"Not found") -> Not found | M367: =IFERROR(INDEX([2]Sheet1!$B:$B,MATCH($D367,[2]Sheet1!$A:$A,0)),"Not found") -> Not found | N367: =IF($M367="Retail",1,0) -> 0 | O367: =IF($M367="Non-Retail",1,0) -> 0
A368: IVF | B368: 42309 | C368: 43404 | D368: Ålandsbanken Obligation Sverige Placeringsfond | E368: 14713626#029 | F368: 27068865 | G368: UCITS | H368: Open-end | I368: Korkorahasto | J368: =IF(ISNUMBER(MATCH($D368,'Lopettaneet 2013->'!$D:$D,0)),INDEX('Lopettaneet 2013->'!$K:$K,MATCH($D368,'Lopettaneet 2013->'!$D:$D,0)),"Continues") -> Merged | K368: =IF($J368="Continues",DATEDIF($B368,TODAY(),"Y"),INDEX('Lopettaneet 2013->'!$L:$L,MATCH($D368,'Lopettaneet 2013->'!$D:$D,0))) -> 2 | L368: =IFERROR(INDEX('[1]30.06.2024'!$H:$H,MATCH($E368,'[1]30.06.2024'!$B:$B,0)),"Not found") -> Not found | M368: =IFERROR(INDEX([2]Sheet1!$B:$B,MATCH($D368,[2]Sheet1!$A:$A,0)),"Not found") -> Not found | N368: =IF($M368="Retail",1,0) -> 0 | O368: =IF($M368="Non-Retail",1,0) -> 0
A369: IVF | B369: 42309 | C369: 55153 | D369: Sijoitusrahasto LähiTapiola Pohjoismaat ESG | E369: 09791339#076 | F369: 27148398 | G369: UCITS | H369: Open-end | I369: Osakerahasto | J369: =IF(ISNUMBER(MATCH($D369,'Lopettaneet 2013->'!$D:$D,0)),INDEX('Lopettaneet 2013->'!$K:$K,MATCH($D369,'Lopettaneet 2013->'!$D:$D,0)),"Continues") -> Continues | K369: =IF($J369="Continues",DATEDIF($B369,TODAY(),"Y"),INDEX('Lopettaneet 2013->'!$L:$L,MATCH($D369,'Lopettaneet 2013->'!$D:$D,0))) -> 9 | L369: =IFERROR(INDEX('[1]30.06.2024'!$H:$H,MATCH($E369,'[1]30.06.2024'!$B:$B,0)),"Not found") -> Not found | M369: =IFERROR(INDEX([2]Sheet1!$B:$B,MATCH($D369,[2]Sheet1!$A:$A,0)),"Not found") -> Retail | N369: =IF($M369="Retail",1,0) -> 1 | O369: =IF($M369="Non-Retail",1,0) -> 0
A370: PEF | B370: 42278 | C370: 55153 | D370: EAI Residential I Ky | E370: 07446590#084 | F370: 26904753 | G370: Non-UCITS | H370: Closed-end | I370: Kiinteistörahasto | J370: =IF(ISNUMBER(MATCH($D370,'Lopettaneet 2013->'!$D:$D,0)),INDEX('Lopettaneet 2013->'!$K:$K,MATCH($D370,'Lopettaneet 2013->'!$D:$D,0)),"Continues") -> Continues | K370: =IF($J370="Continues",DATEDIF($B370,TODAY(),"Y"),INDEX('Lopettaneet 2013->'!$L:$L,MATCH($D370,'Lopettaneet 2013->'!$D:$D,0))) -> 9 | L370: =IFERROR(INDEX('[1]30.06.2024'!$H:$H,MATCH($E370,'[1]30.06.2024'!$B:$B,0)),"Not found") -> Evli-Rahastoyhtiö Oy | M370: =IFERROR(INDEX([2]Sheet1!$B:$B,MATCH($D370,[2]Sheet1!$A:$A,0)),"Not found") -> Non-Retail | N370: =IF($M370="Retail",1,0) -> 0 | O370: =IF($M370="Non-Retail",1,0) -> 1
A371: PEF | B371: 42278 | C371: 55153 | D371: EAI Residential Feeder Fund I Ky | E371: 07446590#085 | F371: 27013303 | G371: Non-UCITS | H371: Closed-end | I371: Kiinteistörahasto | J371: =IF(ISNUMBER(MATCH($D371,'Lopettaneet 2013->'!$D:$D,0)),INDEX('Lopettaneet 2013->'!$K:$K,MATCH($D371,'Lopettaneet 2013->'!$D:$D,0)),"Continues") -> Continues | K371: =IF($J371="Continues",DATEDIF($B371,TODAY(),"Y"),INDEX('Lopettaneet 2013->'!$L:$L,MATCH($D371,'Lopettaneet 2013->'!$D:$D,0))) -> 9 | L371: =IFERROR(INDEX('[1]30.06.2024'!$H:$H,MATCH($E371,'[1]30.06.2024'!$B:$B,0)),"Not found") -> Evli-Rahastoyhtiö Oy | M371: =IFERROR(INDEX([2]Sheet1!$B:$B,MATCH($D371,[2]Sheet1!$A:$A,0)),"Not found") -> Non-Retail | N371: =IF($M371="Retail",1,0) -> 0 | O371: =IF($M371="Non-Retail",1,0) -> 1
...

Sheet Lopettaneet 2013->
A1: Kysely | B1: RaportoinninAloitusPvm | C1: RaportoinninLopetusPvm | D1: Raportoija | E1: RaportoijanRahastotunnus | F1: YksikkoId | G1: Y_tunnus | H1: UCITS_erikoissijoitusrahastotyyppi | I1: Pääomanvaihtelevuus | J1: Rahastotyyppi | K1: Status | L1: Elinaika (y) | M1: Hallinnointiyhtiö | N1: AIF | O1: AIF - retail | P1: AIF - non-retail
A2: PEF | B2: 41974 | C2: 43100 | D2: Oy Wedeco Ab | E2: 15318791#001 | F2: 7218 | G2: 6798092 | H2: Non-UCITS | I2: Closed-end | J2: Buyout-rahasto | K2: Closed | L2: =IF($K2="Continues",DATEDIF($B2,TODAY(),"Y"),DATEDIF($B2,$C2,"Y")) -> 3 | M2: =IFERROR(INDEX('[4]31.03.2024'!$H:$H,MATCH($E2,'[4]31.03.2024'!$B:$B,0)),"Not found") -> Not found | N2: =IFERROR(INDEX([2]Sheet1!$B:$B,MATCH($D2,[2]Sheet1!$A:$A,0)),"Not found") -> Not found | O2: =IF($N2="Retail",1,0) -> 0 | P2: =IF($N2="Non-Retail",1,0) -> 0
A3: PEF | B3: 41974 | C3: 42735 | D3: Finnventure Rahasto V Ky | E3: 07490276#006 | F3: 8486 | G3: 15657523 | H3: Non-UCITS | I3: Closed-end | J3: Buyout-rahasto | K3: Closed | L3: =IF($K3="Continues",DATEDIF($B3,TODAY(),"Y"),DATEDIF($B3,$C3,"Y")) -> 2 | M3: =IFERROR(INDEX('[4]31.03.2024'!$H:$H,MATCH($E3,'[4]31.03.2024'!$B:$B,0)),"Not found") -> Not found | N3: =IFERROR(INDEX([2]Sheet1!$B:$B,MATCH($D3,[2]Sheet1!$A:$A,0)),"Not found") -> Not found | O3: =IF($N3="Retail",1,0) -> 0 | P3: =IF($N3="Non-Retail",1,0) -> 0
A4: PEF | B4: 41974 | C4: 42369 | D4: Maneq Fund 2002 Ky | E4: 19011500#009 | F4: 10400 | G4: 17285698 | H4: Non-UCITS | I4: Closed-end | J4: Buyout-rahasto | K4: Closed | L4: =IF($K4="Continues",DATEDIF($B4,TODAY(),"Y"),DATEDIF($B4,$C4,"Y")) -> 1 | M4: =IFERROR(INDEX('[4]31.03.2024'!$H:$H,MATCH($E4,'[4]31.03.2024'!$B:$B,0)),"Not found") -> Not found | N4: =IFERROR(INDEX([2]Sheet1!$B:$B,MATCH($D4,[2]Sheet1!$A:$A,0)),"Not found") -> Not found | O4: =IF($N4="Retail",1,0) -> 0 | P4: =IF($N4="Non-Retail",1,0) -> 0
A5: PEF | B5: 41974 | C5: 43738 | D5: Finnmezzanine Rahasto III A Ky | E5: 07490276#008 | F5: 10402 | G5: 16020110 | H5: Non-UCITS | I5: Closed-end | J5: Buyout-rahasto | K5: Closed | L5: =IF($K5="Continues",DATEDIF($B5,TODAY(),"Y"),DATEDIF($B5,$C5,"Y")) -> 4 | M5: =IFERROR(INDEX('[4]31.03.2024'!$H:$H,MATCH($E5,'[4]31.03.2024'!$B:$B,0)),"Not found") -> Not found | N5: =IFERROR(INDEX([2]Sheet1!$B:$B,MATCH($D5,[2]Sheet1!$A:$A,0)),"Not found") -> Not found | O5: =IF($N5="Retail",1,0) -> 0 | P5: =IF($N5="Non-Retail",1,0) -> 0
A6: PEF | B6: 41974 | C6: 42369 | D6: Finnmezzanine Rahasto III C Ky | E6: 07490276#011 | F6: 10403 | G6: 16069002 | H6: Non-UCITS | I6: Closed-end | J6: Buyout-rahasto | K6: Closed | L6: =IF($K6="Continues",DATEDIF($B6,TODAY(),"Y"),DATEDIF($B6,$C6,"Y")) -> 1 | M6: =IFERROR(INDEX('[4]31.03.2024'!$H:$H,MATCH($E6,'[4]31.03.2024'!$B:$B,0)),"Not found") -> Not found | N6: =IFERROR(INDEX([2]Sheet1!$B:$B,MATCH($D6,[2]Sheet1!$A:$A,0)),"Not found") -> Not found | O6: =IF($N6="Retail",1,0) -> 0 | P6: =IF($N6="Non-Retail",1,0) -> 0
A7: PEF | B7: 41974 | C7: 43738 | D7: Finnmezzanine Rahasto III B Ky | E7: 07490276#009 | F7: 11037 | G7: 16020137 | H7: Non-UCITS | I7: Closed-end | J7: Buyout-rahasto | K7: Closed | L7: =IF($K7="Continues",DATEDIF($B7,TODAY(),"Y"),DATEDIF($B7,$C7,"Y")) -> 4 | M7: =IFERROR(INDEX('[4]31.03.2024'!$H:$H,MATCH($E7,'[4]31.03.2024'!$B:$B,0)),"Not found") -> Not found | N7: =IFERROR(INDEX([2]Sheet1!$B:$B,MATCH($D7,[2]Sheet1!$A:$A,0)),"Not found") -> Not found | O7: =IF($N7="Retail",1,0) -> 0 | P7: =IF($N7="Non-Retail",1,0) -> 0
A8: PEF | B8: 41974 | C8: 44196 | D8: CapMan Real Estate I Ky | E8: 07491762#001 | F8: 11685 | G8: 19720366 | H8: Non-UCITS | I8: Closed-end | J8: Kiinteistörahasto | K8: Closed | L8: =IF($K8="Continues",DATEDIF($B8,TODAY(),"Y"),DATEDIF($B8,$C8,"Y")) -> 6 | M8: =IFERROR(INDEX('[4]31.03.2024'!$H:$H,MATCH($E8,'[4]31.03.2024'!$B:$B,0)),"Not found") -> Not found | N8: =IFERROR(INDEX([2]Sheet1!$B:$B,MATCH($D8,[2]Sheet1!$A:$A,0)),"Not found") -> Not found | O8: =IF($N8="Retail",1,0) -> 0 | P8: =IF($N8="Non-Retail",1,0) -> 0
A9: PEF | B9: 39783 | C9: 43496 | D9: Placeringsfond SEB Money Manager | E9: 08151401#010 | F9: 11716 | G9: 18799199 | H9: UCITS | I9: Open-end | J9: Rahamarkkinarahasto | K9: Merged | L9: =IF($K9="Continues",DATEDIF($B9,TODAY(),"Y"),DATEDIF($B9,$C9,"Y")) -> 10 | M9: =IFERROR(INDEX('[4]31.03.2024'!$H:$H,MATCH($E9,'[4]31.03.2024'!$B:$B,0)),"Not found") -> Not found | N9: =IFERROR(INDEX([2]Sheet1!$B:$B,MATCH($D9,[2]Sheet1!$A:$A,0)),"Not found") -> Not found | O9: =IF($N9="Retail",1,0) -> 0 | P9: =IF($N9="Non-Retail",1,0) -> 0
A10: MMF | B10: 39783 | C10: 43465 | D10: OP-Euro -sijoitusrahasto | E10: 07439622#016 | F10: 11719 | G10: 11024008 | H10: UCITS | I10: Open-end | J10: Korkorahasto | K10: Closed | L10: =IF($K10="Continues",DATEDIF($B10,TODAY(),"Y"),DATEDIF($B10,$C10,"Y")) -> 10 | M10: =IFERROR(INDEX('[4]31.03.2024'!$H:$H,MATCH($E10,'[4]31.03.2024'!$B:$B,0)),"Not found") -> OP-Rahastoyhtiö Oy | N10: =IFERROR(INDEX([2]Sheet1!$B:$B,MATCH($D10,[2]Sheet1!$A:$A,0)),"Not found") -> Retail | O10: =IF($N10="Retail",1,0) -> 1 | P10: =IF($N10="Non-Retail",1,0) -> 0
A11: MMF | B11: 41122 | C11: 43465 | D11: S-Pankki Lyhyt Korko Sijoitusrahasto | E11: 09791339#004 | F11: 11721 | G11: 20667232 | H11: UCITS | I11: Open-end | J11: Korkorahasto | K11: Closed | L11: =IF($K11="Continues",DATEDIF($B11,TODAY(),"Y"),DATEDIF($B11,$C11,"Y")) -> 6 | M11: =IFERROR(INDEX('[4]31.03.2024'!$H:$H,MATCH($E11,'[4]31.03.2024'!$B:$B,0)),"Not found") -> S-Pankki Rahastoyhtiö Oy | N11: =IFERROR(INDEX([2]Sheet1!$B:$B,MATCH($D11,[2]Sheet1!$A:$A,0)),"Not found") -> Retail | O11: =IF($N11="Retail",1,0) -> 1 | P11: =IF($N11="Non-Retail",1,0) -> 0
A12: MMF | B12: 39783 | C12: 40908 | D12: Placeringsfonden Handelsbanken Euroränta | E12: 11050193#004 | F12: 11723 | G12: 18694434 | H12: UCITS | I12: Open-end | J12: Korkorahasto | K12: Closed | L12: =IF($K12="Continues",DATEDIF($B12,TODAY(),"Y"),DATEDIF($B12,$C12,"Y")) -> 3 | M12: =IFERROR(INDEX('[4]31.03.2024'!$H:$H,MATCH($E12,'[4]31.03.2024'!$B:$B,0)),"Not found") -> Not found | N12: =IFERROR(INDEX([2]Sheet1!$B:$B,MATCH($D12,[2]Sheet1!$A:$A,0)),"Not found") -> Not found | O12: =IF($N12="Retail",1,0) -> 0 | P12: =IF($N12="Non-Retail",1,0) -> 0
A13: MMF | B13: 40909 | C13: 41912 | D13: Placeringsfonden Handelsbanken Euroränta | E13: 11050193#004 | F13: 11723 | G13: 18694434 | H13: UCITS | I13: Open-end | J13: Korkorahasto | K13: Closed | L13: =IF($K13="Continues",DATEDIF($B13,TODAY(),"Y"),DATEDIF($B13,$C13,"Y")) -> 2 | M13: =IFERROR(INDEX('[4]31.03.2024'!$H:$H,MATCH($E13,'[4]31.03.2024'!$B:$B,0)),"Not found") -> Not found | N13: =IFERROR(INDEX([2]Sheet1!$B:$B,MATCH($D13,[2]Sheet1!$A:$A,0)),"Not found") -> Not found | O13: =IF($N13="Retail",1,0) -> 0 | P13: =IF($N13="Non-Retail",1,0) -> 0
A14: MMF | B14: 39783 | C14: 42277 | D14: Sijoitusrahasto Alfred Berg Korko | E14: 09137804#012 | F14: 11727 | G14: 18665836 | H14: UCITS | I14: Open-end | J14: Rahamarkkinarahasto | K14: Merged | L14: =IF($K14="Continues",DATEDIF($B14,TODAY(),"Y"),DATEDIF($B14,$C14,"Y")) -> 6 | M14: =IFERROR(INDEX('[4]31.03.2024'!$H:$H,MATCH($E14,'[4]31.03.2024'!$B:$B,0)),"Not found") -> Not found | N14: =IFERROR(INDEX([2]Sheet1!$B:$B,MATCH($D14,[2]Sheet1!$A:$A,0)),"Not found") -> Not found | O14: =IF($N14="Retail",1,0) -> 0 | P14: =IF($N14="Non-Retail",1,0) -> 0
A15: MMF | B15: 39783 | C15: 40908 | D15: Placeringsfond SEB Likviditetsfond | E15: 08151401#019 | F15: 11734 | G15: NULL | H15: UCITS | I15: Open-end | J15: Korkorahasto | K15: Closed | L15: =IF($K15="Continues",DATEDIF($B15,TODAY(),"Y"),DATEDIF($B15,$C15,"Y")) -> 3 | M15: =IFERROR(INDEX('[4]31.03.2024'!$H:$H,MATCH($E15,'[4]31.03.2024'!$B:$B,0)),"Not found") -> Not found | N15: =IFERROR(INDEX([2]Sheet1!$B:$B,MATCH($D15,[2]Sheet1!$A:$A,0)),"Not found") -> Not found | O15: =IF($N15="Retail",1,0) -> 0 | P15: =IF($N15="Non-Retail",1,0) -> 0
A16: MMF | B16: 40909 | C16: 42704 | D16: Placeringsfond SEB Likviditetsfond | E16: 08151401#019 | F16: 11734 | G16: NULL | H16: UCITS | I16: Open-end | J16: Korkorahasto | K16: Closed | L16: =IF($K16="Continues",DATEDIF($B16,TODAY(),"Y"),DATEDIF($B16,$C16,"Y")) -> 4 | M16: =IFERROR(INDEX('[4]31.03.2024'!$H:$H,MATCH($E16,'[4]31.03.2024'!$B:$B,0)),"Not found") -> Not found | N16: =IFERROR(INDEX([2]Sheet1!$B:$B,MATCH($D16,[2]Sheet1!$A:$A,0)),"Not found") -> Not found | O16: =IF($N16="Retail",1,0) -> 0 | P16: =IF($N16="Non-Retail",1,0) -> 0
A17: MMF | B17: 41974 | C17: 44469 | D17: Veraventure Oy | E17: 08425222#002 | F17: 12364 | G17: 8425222 | H17: Non-UCITS | I17: Closed-end | J17: Venture Capital -rahasto | K17: Closed | L17: =IF($K17="Continues",DATEDIF($B17,TODAY(),"Y"),DATEDIF($B17,$C17,"Y")) -> 6 | M17: =IFERROR(INDEX('[4]31.03.2024'!$H:$H,MATCH($E17,'[4]31.03.2024'!$B:$B,0)),"Not found") -> Not found | N17: =IFERROR(INDEX([2]Sheet1!$B:$B,MATCH($D17,[2]Sheet1!$A:$A,0)),"Not found") -> Not found | O17: =IF($N17="Retail",1,0) -> 0 | P17: =IF($N17="Non-Retail",1,0) -> 0
A18: MMF | B18: 41974 | C18: 43100 | D18: Aloitusrahasto Vera Oy | E18: 08425222#001 | F18: 12372 | G18: 8425142 | H18: Non-UCITS | I18: Closed-end | J18: Venture Capital -rahasto | K18: Closed | L18: =IF($K18="Continues",DATEDIF($B18,TODAY(),"Y"),DATEDIF($B18,$C18,"Y")) -> 3 | M18: =IFERROR(INDEX('[4]31.03.2024'!$H:$H,MATCH($E18,'[4]31.03.2024'!$B:$B,0)),"Not found") -> Not found | N18: =IFERROR(INDEX([2]Sheet1!$B:$B,MATCH($D18,[2]Sheet1!$A:$A,0)),"Not found") -> Not found | O18: =IF($N18="Retail",1,0) -> 0 | P18: =IF($N18="Non-Retail",1,0) -> 0
A19: IVF | B19: 39783 | C19: 41608 | D19: Sijoitusrahasto eQ Lyhyt Rahamarkkinarahasto | E19: 07360527#057 | F19: 12424 | G19: 22343899 | H19: UCITS | I19: Open-end | J19: Rahamarkkinarahasto | K19: Merged | L19: =IF($K19="Continues",DATEDIF($B19,TODAY(),"Y"),DATEDIF($B19,$C19,"Y")) -> 4 | M19: =IFERROR(INDEX('[4]31.03.2024'!$H:$H,MATCH($E19,'[4]31.03.2024'!$B:$B,0)),"Not found") -> Not found | N19: =IFERROR(INDEX([2]Sheet1!$B:$B,MATCH($D19,[2]Sheet1!$A:$A,0)),"Not found") -> Not found | O19: =IF($N19="Retail",1,0) -> 0 | P19: =IF($N19="Non-Retail",1,0) -> 0
A20: MMF | B20: 39783 | C20: 40908 | D20: Placeringsfond SEB Euro Short Rate | E20: 08151401#024 | F20: 12425 | G20: 21644729 | H20: UCITS | I20: Open-end | J20: Korkorahasto | K20: Closed | L20: =IF($K20="Continues",DATEDIF($B20,TODAY(),"Y"),DATEDIF($B20,$C20,"Y")) -> 3 | M20: =IFERROR(INDEX('[4]31.03.2024'!$H:$H,MATCH($E20,'[4]31.03.2024'!$B:$B,0)),"Not found") -> Not found | N20: =IFERROR(INDEX([2]Sheet1!$B:$B,MATCH($D20,[2]Sheet1!$A:$A,0)),"Not found") -> Not found | O20: =IF($N20="Retail",1,0) -> 0 | P20: =IF($N20="Non-Retail",1,0) -> 0
A21: MMF | B21: 40909 | C21: 44712 | D21: Placeringsfond SEB Euro Short Rate | E21: 08151401#024 | F21: 12425 | G21: 21644729 | H21: UCITS | I21: Open-end | J21: Korkorahasto | K21: Closed | L21: =IF($K21="Continues",DATEDIF($B21,TODAY(),"Y"),DATEDIF($B21,$C21,"Y")) -> 10 | M21: =IFERROR(INDEX('[4]31.03.2024'!$H:$H,MATCH($E21,'[4]31.03.2024'!$B:$B,0)),"Not found") -> Not found | N21: =IFERROR(INDEX([2]Sheet1!$B:$B,MATCH($D21,[2]Sheet1!$A:$A,0)),"Not found") -> Not found | O21: =IF($N21="Retail",1,0) -> 0 | P21: =IF($N21="Non-Retail",1,0) -> 0
A22: MMF | B22: 39783 | C22: 40908 | D22: Sijoitusrahasto LähiTapiola Kassakorko | E22: 09791339#058 | F22: 12555 | G22: 21869143 | H22: UCITS | I22: Open-end | J22: Rahamarkkinarahasto | K22: Merged | L22: =IF($K22="Continues",DATEDIF($B22,TODAY(),"Y"),DATEDIF($B22,$C22,"Y")) -> 3 | M22: =IFERROR(INDEX('[4]31.03.2024'!$H:$H,MATCH($E22,'[4]31.03.2024'!$B:$B,0)),"Not found") -> Not found | N22: =IFERROR(INDEX([2]Sheet1!$B:$B,MATCH($D22,[2]Sheet1!$A:$A,0)),"Not found") -> Not found | O22: =IF($N22="Retail",1,0) -> 0 | P22: =IF($N22="Non-Retail",1,0) -> 0
A23: IVF | B23: 40909 | C23: 41121 | D23: Sijoitusrahasto LähiTapiola Kassakorko | E23: 09791339#058 | F23: 12555 | G23: 21869143 | H23: UCITS | I23: Open-end | J23: Rahamarkkinarahasto | K23: Merged | L23: =IF($K23="Continues",DATEDIF($B23,TODAY(),"Y"),DATEDIF($B23,$C23,"Y")) -> 0 | M23: =IFERROR(INDEX('[4]31.03.2024'!$H:$H,MATCH($E23,'[4]31.03.2024'!$B:$B,0)),"Not found") -> Not found | N23: =IFERROR(INDEX([2]Sheet1!$B:$B,MATCH($D23,[2]Sheet1!$A:$A,0)),"Not found") -> Not found | O23: =IF($N23="Retail",1,0) -> 0 | P23: =IF($N23="Non-Retail",1,0) -> 0
A24: PEF | B24: 41122 | C24: 43008 | D24: Sijoitusrahasto LähiTapiola Kassakorko | E24: 09791339#058 | F24: 12555 | G24: 21869143 | H24: UCITS | I24: Open-end | J24: Rahamarkkinarahasto | K24: Merged | L24: =IF($K24="Continues",DATEDIF($B24,TODAY(),"Y"),DATEDIF($B24,$C24,"Y")) -> 5 | M24: =IFERROR(INDEX('[4]31.03.2024'!$H:$H,MATCH($E24,'[4]31.03.2024'!$B:$B,0)),"Not found") -> Not found | N24: =IFERROR(INDEX([2]Sheet1!$B:$B,MATCH($D24,[2]Sheet1!$A:$A,0)),"Not found") -> Not found | O24: =IF($N24="Retail",1,0) -> 0 | P24: =IF($N24="Non-Retail",1,0) -> 0
A25: PEF | B25: 39783 | C25: 43465 | D25: Sijoitusrahasto eQ Lyhyt Korko | E25: 07360527#007 | F25: 12933 | G25: 18001415 | H25: UCITS | I25: Open-end | J25: Korkorahasto | K25: Closed | L25: =IF($K25="Continues",DATEDIF($B25,TODAY(),"Y"),DATEDIF($B25,$C25,"Y")) -> 10 | M25: =IFERROR(INDEX('[4]31.03.2024'!$H:$H,MATCH($E25,'[4]31.03.2024'!$B:$B,0)),"Not found") -> eQ Rahastoyhtiö Oy | N25: =IFERROR(INDEX([2]Sheet1!$B:$B,MATCH($D25,[2]Sheet1!$A:$A,0)),"Not found") -> Retail | O25: =IF($N25="Retail",1,0) -> 1 | P25: =IF($N25="Non-Retail",1,0) -> 0
A26: PEF | B26: 39783 | C26: 43404 | D26: Sijoitusrahasto Danske Invest Rahamarkkina | E26: 06716026#098 | F26: 12936 | G26: 21305882 | H26: UCITS | I26: Open-end | J26: Rahamarkkinarahasto | K26: Merged | L26: =IF($K26="Continues",DATEDIF($B26,TODAY(),"Y"),DATEDIF($B26,$C26,"Y")) -> 9 | M26: =IFERROR(INDEX('[4]31.03.2024'!$H:$H,MATCH($E26,'[4]31.03.2024'!$B:$B,0)),"Not found") -> Not found | N26: =IFERROR(INDEX([2]Sheet1!$B:$B,MATCH($D26,[2]Sheet1!$A:$A,0)),"Not found") -> Not found | O26: =IF($N26="Retail",1,0) -> 0 | P26: =IF($N26="Non-Retail",1,0) -> 0
